Workbook

Sheet Памятка заполнения
A2: Памятка по заполнению формы Бюджета ДДС на ИТ и программу цифровой трансформации
A4: 1. | B4: Форма предполагает заполнение вкладок: Сведения об Организации, Программа ЦТ и План
A8: 2. | B8: Для корректного заполнения формы План необходимо внести сведения по Наименованию Организации и Перечню филиалов на вкладке Сведения об Организации, а также перечень мероприятий программы Цифровой трансформации на вкладке Программа ЦТ
A13: 3. | B13: Заполнение Программы ЦТ является обязательным, если Организации разрабатывала Стратегию Цифровой трансформации. Информация об утверждении Программы ЦТ отражается на вкладке Сведения об Организации
A17: 4. | B17: План расходов включает в себя сведения по всем источникам финансирования, применяемые Организацией, в случае потребности в ИТ товарах/услугах, как для собственных нужд, так и при реализации внешних заказов
A21: 5. | B21: Сводные сведения по расходам на ИТ в разрезе различных источников финансирования на основе сведений Плана представлены на вкладке Свод ДДС
A25: 6. | B25: Дополнительно на вкладке Свод БДДС собирается аналитика по закупкам у Отраслевого оператора по ИТ направлению, а также аналитика о закупке Программного обеспечения, которое включено в реестр
A29: 7. | B29: Для внесения сведений в План о ПО из реестра необходимо внести сведения по номеру записи в поле: Номер в реестре отеч ПО (9), сведения по классу и наименованию ПО будут автоматически заполнены, столбцы: Класс предмета закупки (10) и Предмет закупки(11)
A34: 8. | B34: Если сведения из реестра по какой-то причине не получены, например, неполон перечен ПО на вкладке Реестр отеч ПО или вкладка отсутствует, то внесение сведений проводится в Ручном режиме
A38: 9. | B38: Для определения номера в Реестре отечественного ПО можно использовать вкладки: Реестр отеч ПО или Выдержка из реестра, или использовать поиск на сайте: https://reestr.digital.gov.ru/
A42: 10. | B42: Для планируемого к приобретению ПО вне реестра сведения в План вносятся в ручном режиме, обязательны к заполнению поля: Класс предмета (10) и Предмет закупки(11) или Подробное описание предмета закупки(12)
A46: 11. | B46: При заполнении Плана необходимо отразить расходы, связанные с реализацией мероприятий Программы ЦТ. Сведения по реализации всех мероприятий программы должны найти отражение в Плане
A50: 12. | B50: Если при реализации мероприятия требуется закупка ПО, Оборудования или услуг, то в Плане отражаются расходы отдельными строками с указанием ссылки на номер и наименование мероприятия из Программы ЦТ
... A85: 19. | B85: При работе пользователя с файлом применяется цветовая индикация проверок, которая позволяет определить состав обязательных к заполнению полей по различным типам закупок/расходов. Легенда цветовой индикации представлена справа от заполняемой пользователем формы. Наличие цветовых маркеров не влияет на способность сохранения вносимых сведений в форму, но может стать основанием возврата пользователю форм для доработки

Sheet Сведения об Организации
A1: Контактная информация
A2: Полное наименование организации | C2: Федеральное государственное унитарное предприятие "Научно-технический центр "Заря"
A3: Сокращенное наименование организации | C3: ФГУП "НТЦ "Заря"
A4: Ответственное лицо организации в части информационных технологий (заместитель ГД по ИТ, руководитель подразделения и пр.) | C4: Афонин Владимир Николаевич, Заместитель директора по информационной безопасности
A5: Электронная почта | C5: afonin.vn@ ntc-zarya.ru
A6: Юридический адрес | C6: 123056, г. Москва, ул. 2-я Брестская, дом 9 стр. 1
A7: Фактический адрес | C7: 123056, г. Москва, ул. 2-я Брестская, дом 9 стр. 1
A8: Контактный телефон | C8: +7 (499) 766-22-05, доб 43-04
A9: ИНН организации | C9: 7710030179
A10: Основной вид деятельности (ОКВЭД2) | C10: 74.90.9
A12: Контактные данные ответственного за подготовку отчета работника ИТ-подразделения
A13: ФИО (полностью) | C13: Матвеев Степан Евгеньевич
A14: Наименование подразделения | C14: Отдел технической поддержки
A15: Должность | C15: Главный эксперт
A16: Контактный телефон | C16: (499) 766-22-05 доб. 33-39
A17: Электронная почта | C17: matveev.se@ntc-zarya.ru
A19: Дополнительная информация
A20: Ответственное лицо организации в части цифровизации (заместитель ГД, руководитель по цифровой трансформации и пр.) | C20: Афонин Владимир Николаевич, заместитель директора по информационной безопасности
A21: Стратегия Цифровой трансформации Организации | C21: Утверждена
A22: Программа цифровой трансформации | C22: Да
A24: Дорожная карта по переходу на безбумажный конструкторский и технологический документооборот | C24: Не утверждена
A25: Подключение к ЕСПД | C25: Да
A27: Количество АРМ | C27: 196
A28: в т.ч.
A29: АРМ со сроком полезного использования до 1 года
A30: АРМ со сроком полезного использования от 1 года до 3 лет
A31: АРМ со сроком полезного использования от 3 до 5 лет | C31: 87
A32: АРМ со сроком полезного использования от 5 до 10 лет | C32: 32
A33: АРМ со сроком полезного использования более 10 лет | C33: 5
A34: Количество АРМ с подключением к ЕСПД | C34: 72
A36: Численность организации (вкл. филиалы)* | C36: 182
A37: в т.ч.
B38: 1.1.1. Основные рабочие
B39: 1.1.2.1 ИТР - Конструкторы
B40: 1.1.2.2. ИТР -Технологи
B41: 1.1.2.3. ИТР - Инженеры-испытатели
B42: 1.1.2.4. ИТР - Прочие специалисты | C42: 111.3
B43: 1.1.2.5. ИТР - Руководители | C43: 16
B44: 1.2.1. Вспомогательные рабочие | C44: 7
B45: 1.3.1.1. Руководители - Высший менеджмент | C45: 6
...

Sheet План Факт 2025
A1: Наименование организации | B1: Наименование филиала | C1: Источник финансирования | D1: Статья затрат | E1: Код статьи БДДС | F1: Статья БДДС 3 уровень | G1: ID инвестиционного проекта | H1: Отметка о типе проекта | I1: Объем финансирования инвестиционного проекта, всего, тыс. руб. | J1: Пункт мероприятия Программы ЦТ (Стратегии ЦТ) | K1: Номер в реестре отеч ПО | L1: Класс предмета закупки | M1: Предмет закупки | N1: Подробное описание объекта закупки (товара, работы или услуги) | O1: Отметка о закупке у Отраслевого оператора (Да/Нет) | Q1: Сумма с НДС, тыс. руб
P2: Контрагент | Q2: План 2025 | R2: План (след. Год) | S2: 1-й квартал 2025 | T2: 2-й квартал 2025 | U2: Ожидаемое исполнение 2025 | V2: 3-й квартал 2025 | W2: 4-й квартал 2025 | X2: Месяц поставки | Y2: Год поставки | Z2: План (след. Год+1) | AA2: План (след. Год+2) | AB2: 6 мес 2025 г. | AC2: 6 мес 2025 г. | AD2: Отклонение (руб.) | AE2: Не планировали | AF2: Отклонение (%)_ | AG2: Отклонение (%) | AH2: Комметарии по отклонению от плана
S3: План | T3: План | V3: План | W3: План | X3: План | Y3: План | AB3: План | AC3: Факт
A4: 1 | B4: 2 | C4: 3 | D4: 4 | E4: 5 | F4: 6 | G4: 7 | H4: 8 | I4: 9 | J4: 10 | K4: 11 | L4: 12 | M4: 13 | N4: 14 | O4: 15 | P4: 16 | Q4: 17 | R4: 15 | S4: 18 | T4: 19 | U4: 20 | V4: 21 | W4: 22 | X4: 20 | Y4: 21 | Z4: 22 | AA4: 23 | AB4: 23 | AC4: 24 | AD4: 25 | AE4: 32 | AF4: 14 | AG4: 26 | AH4: 27
A5: ФГУП "НТЦ"Заря" | C5: Инвестиционный_проект | D5: ИТ_оборудование_и_комплектующие_ИП | E5: 42210100. Приобретение, создание, строительство ОС (ИД) | F5: 42210103. Приобретение оборудования для ИТ-инфраструктуры | G5: 075-00011-НП | I5: =SUM(R5,Z5,AA5) -> 1500 | L5: 2. Серверное оборудование, СХД | M5: Закупка системмы хранения данных (отечественного производства) | N5: Совершенствование ИТ-инфраструктуры предприятия с учетом импорьозамещения | O5: Да | Q5: =AB5+V5+W5 -> 1500 | R5: =SUM(S5+T5+V5+W5) -> 1500 | U5: =IF(ISBLANK(AC5),"",AC5+V5+W5) | V5: 1500 | X5: сентябрь | Y5: 2025 | AB5: =SUM(S5:T5) -> 0 | AD5: =IF(ISBLANK(AC5),"",IF(AB5=0,"Поступлений не планировалось",AC5-AB5)) | AE5: =IF($AB5=0,0,1) -> 0 | AF5: =AC5*100/AB5 -> #DIV/0! | AG5: =IF(ISBLANK(AC5),"",AF5-100) | AH5: =IF(($AC5=$AB5),"",IF(ISBLANK($AC5),"", "Укажите причину отклонения"))
A6: ФГУП "НТЦ"Заря" | C6: Инвестиционный_проект | D6: ИТ_оборудование_и_комплектующие_ИП | E6: 42210100. Приобретение, создание, строительство ОС (ИД) | F6: 42210103. Приобретение оборудования для ИТ-инфраструктуры | G6: 075-00011-НП | I6: =SUM(R6,Z6,AA6) -> 19100 | L6: 2. Серверное оборудование, СХД | M6: Серверное оборудование (отечественного производства - DEPO) | N6: Совершенствование ИТ-инфраструктуры предприятия с учетом импортозамещения | O6: Да | P6: ООО "РК-ЦИФРА" | Q6: =AB6+V6+W6 -> 7500 | R6: =SUM(S6+T6+V6+W6) -> 7500 | T6: 7500 | U6: =IF(ISBLANK(AC6),"",AC6+V6+W6) -> 3674.6697 | X6: июнь | Y6: 2025 | Z6: 7600 | AA6: 4000 | AB6: =SUM(S6:T6) -> 7500 | AC6: 3674.6697 | AD6: =IF(ISBLANK(AC6),"",IF(AB6=0,"Поступлений не планировалось",AC6-AB6)) -> -3825.3303 | AE6: =IF($AB6=0,0,1) -> 1 | AF6: =AC6*100/AB6 -> 48.995595 | AG6: =IF(ISBLANK(AC6),"",AF6-100) -> -51.004405 | AH6: Потребность реализована
A7: ФГУП "НТЦ"Заря" | C7: Инвестиционный_проект | D7: ИТ_оборудование_и_комплектующие_ИП | E7: 42210100. Приобретение, создание, строительство ОС (ИД) | F7: 42210103. Приобретение оборудования для ИТ-инфраструктуры | G7: 075-00011-НП | I7: =SUM(R7,Z7,AA7) -> 7840 | L7: 1. Персональные компьютеры, ноутбуки, мониторы, терминалы | M7: АРМ, Ноутбук,ПЭВМ "ЛИС-40" | N7: Закупка ноутбука | O7: Да | P7: ООО "РК-ЦИФРА" | Q7: =AB7+V7+W7 -> 350 | R7: =SUM(S7+T7+V7+W7) -> 350 | T7: 350 | U7: =IF(ISBLANK(AC7),"",AC7+V7+W7) -> 286.4336 | X7: июнь | Y7: 2025 | Z7: =3050+140 -> 3190 | AA7: 4300 | AB7: =SUM(S7:T7) -> 350 | AC7: 286.4336 | AD7: =IF(ISBLANK(AC7),"",IF(AB7=0,"Поступлений не планировалось",AC7-AB7)) -> -63.5664 | AE7: =IF($AB7=0,0,1) -> 1 | AF7: =AC7*100/AB7 -> 81.838171 | AG7: =IF(ISBLANK(AC7),"",AF7-100) -> -18.161829 | AH7: Потребность реализована
A8: ФГУП "НТЦ"Заря" | C8: Операционный_бюджет | D8: ИТ_оборудование_и_комплектующие | L8: 7. Прочее оборудование | M8: Комплектующие для АРМ | N8: Закупка комплектующих для АРМ | O8: Да | Q8: =AB8+V8+W8 -> 660 | R8: =SUM(S8+T8+V8+W8) -> 660 | T8: 660 | U8: =IF(ISBLANK(AC8),"",AC8+V8+W8) | X8: июнь | Y8: 2025 | Z8: 680 | AA8: 690 | AB8: =SUM(S8:T8) -> 660 | AD8: =IF(ISBLANK(AC8),"",IF(AB8=0,"Поступлений не планировалось",AC8-AB8)) | AE8: =IF($AB8=0,0,1) -> 1 | AF8: =AC8*100/AB8 -> 0 | AG8: =IF(ISBLANK(AC8),"",AF8-100)
A9: ФГУП "НТЦ"Заря" | C9: Операционный_бюджет | D9: Запчасти_и_расходные_материалы_к_ИТ_оборудованию | L9: 6. Печатное оборудование и сканеры | M9: Картриджи для принтеров | N9: Закупка картриджей для принтеров | O9: Да | Q9: =AB9+V9+W9 -> 1200 | R9: =SUM(S9+T9+V9+W9) -> 1200 | U9: =IF(ISBLANK(AC9),"",AC9+V9+W9) | V9: 1200 | X9: сентябрь | Y9: 2025 | Z9: 1500 | AA9: 1600 | AB9: =SUM(S9:T9) -> 0 | AD9: =IF(ISBLANK(AC9),"",IF(AB9=0,"Поступлений не планировалось",AC9-AB9)) | AE9: =IF($AB9=0,0,1) -> 0 | AF9: =AC9*100/AB9 -> #DIV/0! | AG9: =IF(ISBLANK(AC9),"",AF9-100)
A10: ФГУП "НТЦ"Заря" | C10: Операционный_бюджет | D10: ИТ_оборудование_и_комплектующие | L10: 7. Прочее оборудование | M10: Системные блоки | N10: Закупка системных блоков | O10: Да | Q10: =AB10+V10+W10 -> 4000 | R10: =SUM(S10+T10+V10+W10) -> 4000 | U10: =IF(ISBLANK(AC10),"",AC10+V10+W10) | V10: 4000 | X10: сентябрь | Y10: 2025 | Z10: 4300 | AA10: 4500 | AB10: =SUM(S10:T10) -> 0 | AD10: =IF(ISBLANK(AC10),"",IF(AB10=0,"Поступлений не планировалось",AC10-AB10)) | AE10: =IF($AB10=0,0,1) -> 0 | AF10: =AC10*100/AB10 -> #DIV/0! | AG10: =IF(ISBLANK(AC10),"",AF10-100)
A11: ФГУП "НТЦ"Заря" | C11: Операционный_бюджет | D11: Программное_обеспечение_лицензии | L11: 2.2 - Программы обслуживания | M11: БД "Госзаказ" Лицензия | N11: Закупка лицензии БД "Госзаказ" | O11: Нет | Q11: =AB11+V11+W11 -> 100 | R11: =SUM(S11+T11+V11+W11) -> 100 | S11: 100 | U11: =IF(ISBLANK(AC11),"",AC11+V11+W11) | X11: март | Y11: 2025 | Z11: 130 | AA11: 150 | AB11: =SUM(S11:T11) -> 100 | AD11: =IF(ISBLANK(AC11),"",IF(AB11=0,"Поступлений не планировалось",AC11-AB11)) | AE11: =IF($AB11=0,0,1) -> 1 | AF11: =AC11*100/AB11 -> 0 | AG11: =IF(ISBLANK(AC11),"",AF11-100)
A12: ФГУП "НТЦ"Заря" | C12: Операционный_бюджет | D12: Программное_обеспечение_лицензии | K12: 212 | L12: 2.2 - Программы обслуживания | M12: Лицензия Консультант Плюс | N12: Закупка лицензий Когсультант плюс | O12: Нет | P12: ООО "ЭЛКОД" | Q12: =AB12+V12+W12 -> 1000 | R12: =SUM(S12+T12+V12+W12) -> 1000 | U12: =IF(ISBLANK(AC12),"",AC12+V12+W12) -> 2200 | W12: 1000 | X12: ноябрь | Y12: 2025 | Z12: 1100 | AA12: 1200 | AB12: =SUM(S12:T12) -> 0 | AC12: 1200 | AD12: =IF(ISBLANK(AC12),"",IF(AB12=0,"Поступлений не планировалось",AC12-AB12)) -> Поступлений не планировалось | AE12: =IF($AB12=0,0,1) -> 0 | AF12: =AC12*100/AB12 -> #DIV/0! | AG12: =IF(ISBLANK(AC12),"",AF12-100) -> #DIV/0! | AH12: Удорожание лицензий
A13: ФГУП "НТЦ"Заря" | C13: Операционный_бюджет | D13: Программное_обеспечение_лицензии | L13: 2.2 - Программы обслуживания | M13: Автоматизированная система АС ФинПлан | N13: Закупка автоматезированной системы АС ФинПлан | O13: Нет | Q13: =AB13+V13+W13 -> 100 | R13: =SUM(S13+T13+V13+W13) -> 100 | S13: 100 | U13: =IF(ISBLANK(AC13),"",AC13+V13+W13) | X13: март | Y13: 2025 | Z13: 120 | AA13: 140 | AB13: =SUM(S13:T13) -> 100 | AD13: =IF(ISBLANK(AC13),"",IF(AB13=0,"Поступлений не планировалось",AC13-AB13)) | AE13: =IF($AB13=0,0,1) -> 1 | AF13: =AC13*100/AB13 -> 0 | AG13: =IF(ISBLANK(AC13),"",AF13-100)
A14: ФГУП "НТЦ"Заря" | C14: Операционный_бюджет | D14: Программное_обеспечение_лицензии | K14: 20157 | L14: 1.4 - Программное обеспечение интернета вещей, робототехники и сенсорики | M14: Сопровождение сайта | N14: Сопровождение сайта | O14: Нет | Q14: =AB14+V14+W14 -> 700 | R14: =SUM(S14+T14+V14+W14) -> 700 | T14: 700 | U14: =IF(ISBLANK(AC14),"",AC14+V14+W14) | X14: июнь | Y14: 2025 | Z14: 750 | AA14: 900 | AB14: =SUM(S14:T14) -> 700 | AD14: =IF(ISBLANK(AC14),"",IF(AB14=0,"Поступлений не планировалось",AC14-AB14)) | AE14: =IF($AB14=0,0,1) -> 1 | AF14: =AC14*100/AB14 -> 0 | AG14: =IF(ISBLANK(AC14),"",AF14-100)
A15: ФГУП "НТЦ"Заря" | C15: Операционный_бюджет | D15: ИТ_оборудование_и_комплектующие | L15: 7. Прочее оборудование | M15: Оптические диски | N15: Закупка оптических дисков | O15: Да | P15: ИП Столбов Геннадий Сергеевич | Q15: =AB15+V15+W15 -> 90 | R15: =SUM(S15+T15+V15+W15) -> 90 | T15: 90 | U15: =IF(ISBLANK(AC15),"",AC15+V15+W15) -> 50 | X15: июнь | Y15: 2025 | Z15: 100 | AA15: 110 | AB15: =SUM(S15:T15) -> 90 | AC15: 50 | AD15: =IF(ISBLANK(AC15),"",IF(AB15=0,"Поступлений не планировалось",AC15-AB15)) -> -40 | AE15: =IF($AB15=0,0,1) -> 1 | AF15: =AC15*100/AB15 -> 55.555556 | AG15: =IF(ISBLANK(AC15),"",AF15-100) -> -44.444444 | AH15: Укажите причину отклонения
A16: ФГУП "НТЦ"Заря" | C16: Операционный_бюджет | D16: Услуги_связи | L16: 2.2 - Программы обслуживания | M16: Интернет, выделенный канал связи | N16: Интернет, выделенный канал связи | O16: Нет | P16: ООО "Наука-Связь" | Q16: =AB16+V16+W16 -> 1100 | R16: =SUM(S16+T16+V16+W16) -> 1100 | S16: 1100 | U16: =IF(ISBLANK(AC16),"",AC16+V16+W16) -> 546 | X16: март | Y16: 2025 | Z16: 1200 | AA16: 1300 | AB16: =SUM(S16:T16) -> 1100 | AC16: 546 | AD16: =IF(ISBLANK(AC16),"",IF(AB16=0,"Поступлений не планировалось",AC16-AB16)) -> -554 | AE16: =IF($AB16=0,0,1) -> 1 | AF16: =AC16*100/AB16 -> 49.636364 | AG16: =IF(ISBLANK(AC16),"",AF16-100) -> -50.363636 | AH16: Скидка провайдера
A17: ФГУП "НТЦ"Заря" | C17: Операционный_бюджет | D17: Программное_обеспечение_лицензии | L17: 2.2 - Программы обслуживания | M17: Электронный журнал "Финансовый директор" | N17: Закупка электронного журнала "Финансовый директор" | O17: Нет | Q17: =AB17+V17+W17 -> 30 | R17: =SUM(S17+T17+V17+W17) -> 30 | S17: 30 | U17: =IF(ISBLANK(AC17),"",AC17+V17+W17) | X17: март | Y17: 2025 | Z17: 50 | AA17: 70 | AB17: =SUM(S17:T17) -> 30 | AD17: =IF(ISBLANK(AC17),"",IF(AB17=0,"Поступлений не планировалось",AC17-AB17)) | AE17: =IF($AB17=0,0,1) -> 1 | AF17: =AC17*100/AB17 -> 0 | AG17: =IF(ISBLANK(AC17),"",AF17-100)
A18: ФГУП "НТЦ"Заря" | C18: Операционный_бюджет | D18: ИТ_оборудование_и_комплектующие | L18: 7. Прочее оборудование | M18: Мониторы для АРМ | N18: Закупка мониторов для АРМ | O18: Да | Q18: =AB18+V18+W18 -> 1000 | R18: =SUM(S18+T18+V18+W18) -> 1000 | U18: =IF(ISBLANK(AC18),"",AC18+V18+W18) | V18: 1000 | X18: сентябрь | Y18: 2025 | Z18: 1200 | AA18: 1500 | AB18: =SUM(S18:T18) -> 0 | AD18: =IF(ISBLANK(AC18),"",IF(AB18=0,"Поступлений не планировалось",AC18-AB18)) | AE18: =IF($AB18=0,0,1) -> 0 | AF18: =AC18*100/AB18 -> #DIV/0! | AG18: =IF(ISBLANK(AC18),"",AF18-100)
A19: ФГУП "НТЦ"Заря" | C19: Операционный_бюджет | D19: Услуги_внешней_техподдержки | L19: 2.2 - Программы обслуживания | M19: Техническая поддержка UserGate | N19: Техническая поддержка UserGate | O19: Нет | Q19: =AB19+V19+W19 -> 1200 | R19: =SUM(S19+T19+V19+W19) -> 1200 | T19: 1200 | U19: =IF(ISBLANK(AC19),"",AC19+V19+W19) | X19: июнь | Y19: 2025 | Z19: 1400 | AA19: 1600 | AB19: =SUM(S19:T19) -> 1200 | AD19: =IF(ISBLANK(AC19),"",IF(AB19=0,"Поступлений не планировалось",AC19-AB19)) | AE19: =IF($AB19=0,0,1) -> 1 | AF19: =AC19*100/AB19 -> 0 | AG19: =IF(ISBLANK(AC19),"",AF19-100)
A20: ФГУП "НТЦ"Заря" | C20: Операционный_бюджет | D20: Программное_обеспечение_лицензии | L20: 2.2 - Программы обслуживания | M20: Сопровождение 1С | N20: Сопровождение 1С | O20: Да | P20: АО "Организация "Агат" | Q20: =AB20+V20+W20 -> 5500 | R20: =SUM(S20+T20+V20+W20) -> 5500 | U20: =IF(ISBLANK(AC20),"",AC20+V20+W20) -> 8730 | W20: 5500 | X20: ноябрь | Y20: 2025 | Z20: 6000 | AA20: 6500 | AB20: =SUM(S20:T20) -> 0 | AC20: 3230 | AD20: =IF(ISBLANK(AC20),"",IF(AB20=0,"Поступлений не планировалось",AC20-AB20)) -> Поступлений не планировалось | AE20: =IF($AB20=0,0,1) -> 0 | AF20: =AC20*100/AB20 -> #DIV/0! | AG20: =IF(ISBLANK(AC20),"",AF20-100) -> #DIV/0! | AH20: Отказ от модуля 1С:РМ
A21: ФГУП "НТЦ"Заря" | C21: Операционный_бюджет | D21: Программное_обеспечение_лицензии | L21: 2.2 - Программы обслуживания | M21: Сопровождение планово целевого планирования | N21: Сопровождение планово целевого планирования | O21: Да | Q21: =AB21+V21+W21 -> 1100 | R21: =SUM(S21+T21+V21+W21) -> 1100 | T21: 1100 | U21: =IF(ISBLANK(AC21),"",AC21+V21+W21) | X21: июнь | Y21: 2025 | Z21: 1300 | AA21: 1500 | AB21: =SUM(S21:T21) -> 1100 | AD21: =IF(ISBLANK(AC21),"",IF(AB21=0,"Поступлений не планировалось",AC21-AB21)) | AE21: =IF($AB21=0,0,1) -> 1 | AF21: =AC21*100/AB21 -> 0 | AG21: =IF(ISBLANK(AC21),"",AF21-100)
A22: ФГУП "НТЦ"Заря" | C22: Операционный_бюджет | D22: ИТ_оборудование_и_комплектующие | L22: 7. Прочее оборудование | M22: Внедрение системы видеоинформирования | N22: Закупка телевизоров | O22: Да | P22: ООО "МВМ" | Q22: =AB22+V22+W22 -> 600 | R22: =SUM(S22+T22+V22+W22) -> 600 | T22: 600 | U22: =IF(ISBLANK(AC22),"",AC22+V22+W22) -> 98 | X22: июнь | Y22: 2025 | Z22: 200 | AA22: 200 | AB22: =SUM(S22:T22) -> 600 | AC22: 98 | AD22: =IF(ISBLANK(AC22),"",IF(AB22=0,"Поступлений не планировалось",AC22-AB22)) -> -502 | AE22: =IF($AB22=0,0,1) -> 1 | AF22: =AC22*100/AB22 -> 16.333333 | AG22: =IF(ISBLANK(AC22),"",AF22-100) -> -83.666667 | AH22: Потребность реализована
A23: ФГУП "НТЦ"Заря" | C23: Операционный_бюджет | D23: Программное_обеспечение_лицензии | K23: 1247 | L23: 2.2 - Программы обслуживания | M23: Открытая система обработки заявок | N23: Закупка открытой системы обработки заявок | O23: Нет | Q23: =AB23+V23+W23 -> 300 | R23: =SUM(S23+T23+V23+W23) -> 300 | T23: 300 | U23: =IF(ISBLANK(AC23),"",AC23+V23+W23) | X23: июнь | Y23: 2025 | Z23: 400 | AA23: 500 | AB23: =SUM(S23:T23) -> 300 | AD23: =IF(ISBLANK(AC23),"",IF(AB23=0,"Поступлений не планировалось",AC23-AB23)) | AE23: =IF($AB23=0,0,1) -> 1 | AF23: =AC23*100/AB23 -> 0 | AG23: =IF(ISBLANK(AC23),"",AF23-100)
A24: ФГУП "НТЦ"Заря" | C24: Операционный_бюджет | D24: Программное_обеспечение_лицензии | K24: 14647 | L24: 2.2 - Программы обслуживания | M24: Отечественная корпоротивная почта | N24: Закупка отечественной корпоротивной почты | O24: Нет | Q24: =AB24+V24+W24 -> 1000 | R24: =SUM(S24+T24+V24+W24) -> 1000 | T24: 1000 | U24: =IF(ISBLANK(AC24),"",AC24+V24+W24) | X24: июнь | Y24: 2025 | Z24: 120 | AA24: 140 | AB24: =SUM(S24:T24) -> 1000 | AD24: =IF(ISBLANK(AC24),"",IF(AB24=0,"Поступлений не планировалось",AC24-AB24)) | AE24: =IF($AB24=0,0,1) -> 1 | AF24: =AC24*100/AB24 -> 0 | AG24: =IF(ISBLANK(AC24),"",AF24-100)
A25: ФГУП "НТЦ"Заря" | C25: Операционный_бюджет | D25: Программное_обеспечение_лицензии | K25: 5256 | L25: 2.2 - Программы обслуживания | M25: Отечественное офисное приложение | N25: Закупка отечественного офисного приложения | O25: Нет | Q25: =AB25+V25+W25 -> 800 | R25: =SUM(S25+T25+V25+W25) -> 800 | T25: 800 | U25: =IF(ISBLANK(AC25),"",AC25+V25+W25) | X25: июнь | Y25: 2025 | Z25: 300 | AA25: 350 | AB25: =SUM(S25:T25) -> 800 | AD25: =IF(ISBLANK(AC25),"",IF(AB25=0,"Поступлений не планировалось",AC25-AB25)) | AE25: =IF($AB25=0,0,1) -> 1 | AF25: =AC25*100/AB25 -> 0 | AG25: =IF(ISBLANK(AC25),"",AF25-100)
A26: ФГУП "НТЦ"Заря" | C26: Операционный_бюджет | D26: Программное_обеспечение_лицензии | L26: 2.2 - Программы обслуживания | M26: Техническая поддержка для многофункциональных устройств | N26: Техническая поддержка для многофункциональных устройств | O26: Нет | Q26: =AB26+V26+W26 -> 200 | R26: =SUM(S26+T26+V26+W26) -> 200 | T26: 200 | U26: =IF(ISBLANK(AC26),"",AC26+V26+W26) | X26: июнь | Y26: 2025 | Z26: 250 | AA26: 300 | AB26: =SUM(S26:T26) -> 200 | AD26: =IF(ISBLANK(AC26),"",IF(AB26=0,"Поступлений не планировалось",AC26-AB26)) | AE26: =IF($AB26=0,0,1) -> 1 | AF26: =AC26*100/AB26 -> 0 | AG26: =IF(ISBLANK(AC26),"",AF26-100)
A27: ФГУП "НТЦ"Заря" | C27: Операционный_бюджет | D27: Программное_обеспечение_лицензии | L27: 2.2 - Программы обслуживания | M27: Техническая поддержка АТС | N27: Доработка телефонной станции | O27: Нет | Q27: =AB27+V27+W27 -> 500 | R27: =SUM(S27+T27+V27+W27) -> 500 | T27: 500 | U27: =IF(ISBLANK(AC27),"",AC27+V27+W27) | X27: июнь | Y27: 2025 | Z27: 700 | AA27: 850 | AB27: =SUM(S27:T27) -> 500 | AD27: =IF(ISBLANK(AC27),"",IF(AB27=0,"Поступлений не планировалось",AC27-AB27)) | AE27: =IF($AB27=0,0,1) -> 1 | AF27: =AC27*100/AB27 -> 0 | AG27: =IF(ISBLANK(AC27),"",AF27-100)
A28: ФГУП "НТЦ"Заря" | C28: Операционный_бюджет | D28: Программное_обеспечение_лицензии | K28: 113 | L28: 2.2 - Программы обслуживания | M28: Лицензия V-Gate | N28: Внедрение лицензий V-Gate | O28: Да | Q28: =AB28+V28+W28 -> 500 | R28: =SUM(S28+T28+V28+W28) -> 500 | T28: 500 | U28: =IF(ISBLANK(AC28),"",AC28+V28+W28) | X28: июнь | Y28: 2025 | Z28: 120 | AA28: 150 | AB28: =SUM(S28:T28) -> 500 | AD28: =IF(ISBLANK(AC28),"",IF(AB28=0,"Поступлений не планировалось",AC28-AB28)) | AE28: =IF($AB28=0,0,1) -> 1 | AF28: =AC28*100/AB28 -> 0 | AG28: =IF(ISBLANK(AC28),"",AF28-100)
A29: ФГУП "НТЦ "Заря" | C29: Операционный_бюджет | D29: Программное_обеспечение_лицензии | L29: 2.2 - Программы обслуживания | M29: Техническая поддержка АКПШ Континент | N29: Техническая поддержка АКПШ Континент | O29: Нет | Q29: =AB29+V29+W29 -> 350 | R29: =SUM(S29+T29+V29+W29) -> 350 | U29: =IF(ISBLANK(AC29),"",AC29+V29+W29) | V29: 350 | X29: сентябрь | Y29: 2025 | Z29: 370 | AA29: 390 | AB29: =SUM(S29:T29) -> 0 | AD29: =IF(ISBLANK(AC29),"",IF(AB29=0,"Поступлений не планировалось",AC29-AB29)) | AE29: =IF($AB29=0,0,1) -> 0 | AF29: =AC29*100/AB29 -> #DIV/0! | AG29: =IF(ISBLANK(AC29),"",AF29-100)
A30: ФГУП "НТЦ "Заря" | C30: Операционный_бюджет | D30: ИТ_оборудование_и_комплектующие | I30: =Q30 -> 0 | L30: 2. Серверное оборудование, СХД | M30: Источник бесперебойного электропитания для серверов | N30: Закупка источников бесперебойного электропитания для серверов | O30: Да | Q30: =AB30+V30+W30 -> 0 | R30: =SUM(S30+T30+V30+W30) -> 0 | U30: =IF(ISBLANK(AC30),"",AC30+V30+W30) | W30: =200*0 -> 0 | X30: сентябрь | Y30: 2025 | Z30: 200 | AA30: 250 | AB30: =SUM(S30:T30) -> 0 | AD30: =IF(ISBLANK(AC30),"",IF(AB30=0,"Поступлений не планировалось",AC30-AB30)) | AE30: =IF($AB30=0,0,1) -> 0 | AF30: =AC30*100/AB30 -> #DIV/0! | AG30: =IF(ISBLANK(AC30),"",AF30-100)
A31: ФГУП "НТЦ "Заря" | C31: Операционный_бюджет | D31: Программное_обеспечение_лицензии | K31: 11898 | L31: 3.15 - Средства обнаружения угроз и расследования сетевых инцидентов | M31: Закупка подсистемы мониторинга событий информационной безопасности | N31: Поставка неисключительных лицензий на использование подсистема мониторинга событий информационной безопасности MaxPatrol SIEM | O31: Нет | Q31: =AB31+V31+W31 -> 0 | R31: =SUM(S31+T31+V31+W31) -> 0 | U31: =IF(ISBLANK(AC31),"",AC31+V31+W31) | W31: 0 | X31: Каждый квартал | Y31: 2025 | AB31: =SUM(S31:T31) -> 0 | AD31: =IF(ISBLANK(AC31),"",IF(AB31=0,"Поступлений не планировалось",AC31-AB31)) | AE31: =IF($AB31=0,0,1) -> 0 | AF31: =AC31*100/AB31 -> #DIV/0! | AG31: =IF(ISBLANK(AC31),"",AF31-100)
A32: ФГУП "НТЦ "Заря" | C32: Операционный_бюджет | D32: Программное_обеспечение_лицензии | K32: 369 | L32: 1.2 - Встроенные системные программы - операционные системы | M32: Операционная система Astra Linux для серверов | N32: Оказание услуг по предоставлению неисключительных прав (лицензий) на использование отечественной операционной системы Astra Linux 1.7 (серверная) | O32: Да | Q32: =AB32+V32+W32 -> 500 | R32: =SUM(S32+T32+V32+W32) -> 500 | S32: 500 | U32: =IF(ISBLANK(AC32),"",AC32+V32+W32) | X32: июнь | Y32: 2025 | Z32: 300 | AA32: 350 | AB32: =SUM(S32:T32) -> 500 | AD32: =IF(ISBLANK(AC32),"",IF(AB32=0,"Поступлений не планировалось",AC32-AB32)) | AE32: =IF($AB32=0,0,1) -> 1 | AF32: =AC32*100/AB32 -> 0 | AG32: =IF(ISBLANK(AC32),"",AF32-100)
A33: ФГУП "НТЦ "Заря" | C33: Операционный_бюджет | D33: Программное_обеспечение_лицензии | K33: 11953 | L33: 3.17 - Средства автоматизации процессов информационной безопасности | M33: Закупка подсистемы мониторинга событий информационной безопасности | N33: Поставка неисключительных лицензий на использование подсистемы анализа защищенности MaxPatrol VM | O33: Да | Q33: =AB33+V33+W33 -> 4600 | R33: =SUM(S33+T33+V33+W33) -> 4600 | T33: 4600 | U33: =IF(ISBLANK(AC33),"",AC33+V33+W33) | X33: июнь | Y33: 2025 | Z33: 2100 | AA33: 2300 | AB33: =SUM(S33:T33) -> 4600 | AD33: =IF(ISBLANK(AC33),"",IF(AB33=0,"Поступлений не планировалось",AC33-AB33)) | AE33: =IF($AB33=0,0,1) -> 1 | AF33: =AC33*100/AB33 -> 0 | AG33: =IF(ISBLANK(AC33),"",AF33-100)
A34: ФГУП "НТЦ "Заря" | C34: Операционный_бюджет | D34: Программное_обеспечение_лицензии | K34: 4984 | L34: 2.4 - Средства виртуализации | M34: Закупка сертифицированной ФСТЭК России системы виртуализации | N34: Поставка неисключительных лицензий на использование системы виртуализации ZVirt | O34: Да | Q34: =AB34+V34+W34 -> 2200 | R34: =SUM(S34+T34+V34+W34) -> 2200 | T34: 2200 | U34: =IF(ISBLANK(AC34),"",AC34+V34+W34) | X34: июнь | Y34: 2025 | Z34: 700 | AA34: 800 | AB34: =SUM(S34:T34) -> 2200 | AD34: =IF(ISBLANK(AC34),"",IF(AB34=0,"Поступлений не планировалось",AC34-AB34)) | AE34: =IF($AB34=0,0,1) -> 1 | AF34: =AC34*100/AB34 -> 0 | AG34: =IF(ISBLANK(AC34),"",AF34-100)
A35: ФГУП "НТЦ "Заря" | C35: Операционный_бюджет | D35: Программное_обеспечение_лицензии | K35: 369 | L35: 1.2 - Встроенные системные программы - операционные системы | M35: Операционная система Astra Linux для рабочих станций | N35: Оказание услуг по предоставлению неисключительных прав (лицензий) на использование отечественной операционной системы Astra Linux 1.7 (для рабочих станций) | O35: Да | Q35: =AB35+V35+W35 -> 3700 | R35: =SUM(S35+T35+V35+W35) -> 3700 | U35: =IF(ISBLANK(AC35),"",AC35+V35+W35) | V35: 3700 | X35: сентябрь | Y35: 2025 | Z35: 1200 | AA35: 1100 | AB35: =SUM(S35:T35) -> 0 | AD35: =IF(ISBLANK(AC35),"",IF(AB35=0,"Поступлений не планировалось",AC35-AB35)) | AE35: =IF($AB35=0,0,1) -> 0 | AF35: =AC35*100/AB35 -> #DIV/0! | AG35: =IF(ISBLANK(AC35),"",AF35-100)
A36: ФГУП "НТЦ "Заря" | C36: Операционный_бюджет | D36: Программное_обеспечение_лицензии | K36: 6808 | L36: 3.13 - Средства резервного копирования | M36: Средство резервного копирования Кибер Бэкап | N36: Поставка неисключительных прав на использования средства резервного копирования Кибер Бэкап | O36: Да | Q36: =AB36+V36+W36 -> 540 | R36: =SUM(S36+T36+V36+W36) -> 540 | U36: =IF(ISBLANK(AC36),"",AC36+V36+W36) | V36: 540 | X36: сентябрь | Y36: 2025 | Z36: 250 | AA36: 280 | AB36: =SUM(S36:T36) -> 0 | AD36: =IF(ISBLANK(AC36),"",IF(AB36=0,"Поступлений не планировалось",AC36-AB36)) | AE36: =IF($AB36=0,0,1) -> 0 | AF36: =AC36*100/AB36 -> #DIV/0! | AG36: =IF(ISBLANK(AC36),"",AF36-100)
A37: ФГУП "НТЦ "Заря" | C37: Операционный_бюджет | D37: Программное_обеспечение_лицензии | K37: 203 | L37: 3.6 - Средства антивирусной защиты | M37: Kaspersky Security для почтовых сереров | N37: Поставка неисключительных прав на использования средства Kaspersky Security | O37: Да | P37: ООО "РК-ЦИФРА" | Q37: =AB37+V37+W37 -> 560 | R37: =SUM(S37+T37+V37+W37) -> 560 | U37: =IF(ISBLANK(AC37),"",AC37+V37+W37) -> 928 | V37: 560 | X37: сентябрь | Y37: 2025 | Z37: 350 | AA37: 400 | AB37: =SUM(S37:T37) -> 0 | AC37: 368 | AD37: =IF(ISBLANK(AC37),"",IF(AB37=0,"Поступлений не планировалось",AC37-AB37)) -> Поступлений не планировалось | AE37: =IF($AB37=0,0,1) -> 0 | AF37: =AC37*100/AB37 -> #DIV/0! | AG37: =IF(ISBLANK(AC37),"",AF37-100) -> #DIV/0! | AH37: Скидка поставщика
A38: ФГУП "НТЦ "Заря" | C38: Операционный_бюджет | D38: Аренда_оборудования_и_вычислительных_мощностей | L38: 7. Прочее оборудование | M38: Аренда стойко-места под серверное оборудование в ЦОД | N38: Аренда стойко-места под серверное оборудование в ЦОД для развертывания подсистемы мониторинга событий информационной безопасности | O38: Да | Q38: =AB38+V38+W38 -> 1100 | R38: =SUM(S38+T38+V38+W38) -> 1100 | T38: 1100 | U38: =IF(ISBLANK(AC38),"",AC38+V38+W38) | X38: май | Y38: 2025 | Z38: 1300 | AA38: 1500 | AB38: =SUM(S38:T38) -> 1100 | AD38: =IF(ISBLANK(AC38),"",IF(AB38=0,"Поступлений не планировалось",AC38-AB38)) | AE38: =IF($AB38=0,0,1) -> 1 | AF38: =AC38*100/AB38 -> 0 | AG38: =IF(ISBLANK(AC38),"",AF38-100) | AH38: =IF(($AC38=$AB38),"",IF(ISBLANK($AC38),"", "Укажите причину отклонения"))
A39: ФГУП "НТЦ "Заря" | C39: Операционный_бюджет | D39: Ремонт_ИТ_инфраструктуры | L39: 7. Прочее оборудование | M39: Услуга по ремонту | N39: Ремонт сетевого оборудования | O39: Нет | Q39: =AB39+V39+W39 -> 150 | R39: =SUM(S39+T39+V39+W39) -> 150 | U39: =IF(ISBLANK(AC39),"",AC39+V39+W39) | V39: 150 | X39: сентябрь | Y39: 2025 | Z39: 160 | AA39: 160 | AB39: =SUM(S39:T39) -> 0 | AD39: =IF(ISBLANK(AC39),"",IF(AB39=0,"Поступлений не планировалось",AC39-AB39)) | AE39: =IF($AB39=0,0,1) -> 0 | AF39: =AC39*100/AB39 -> #DIV/0! | AG39: =IF(ISBLANK(AC39),"",AF39-100) | AH39: =IF(($AC39=$AB39),"",IF(ISBLANK($AC39),"", "Укажите причину отклонения"))
A40: ФГУП "НТЦ "Заря" | C40: Операционный_бюджет | D40: Ремонт_ИТ_инфраструктуры | L40: 7. Прочее оборудование | M40: Услуга по ремонту | N40: Ремонт каналообразующего оборудования | O40: Нет | Q40: =AB40+V40+W40 -> 200 | R40: =SUM(S40+T40+V40+W40) -> 200 | S40: 50 | T40: 50 | U40: =IF(ISBLANK(AC40),"",AC40+V40+W40) | V40: 50 | W40: 50 | X40: Каждый квартал | Y40: 2025 | Z40: 200 | AA40: 200 | AB40: =SUM(S40:T40) -> 100 | AD40: =IF(ISBLANK(AC40),"",IF(AB40=0,"Поступлений не планировалось",AC40-AB40)) | AE40: =IF($AB40=0,0,1) -> 1 | AF40: =AC40*100/AB40 -> 0 | AG40: =IF(ISBLANK(AC40),"",AF40-100) | AH40: =IF(($AC40=$AB40),"",IF(ISBLANK($AC40),"", "Укажите причину отклонения"))
...

Sheet План 2026-2028
A1: Наименование организации | B1: Наименование филиала | C1: Источник финансирования | D1: Статья затрат | E1: Код статьи БДДС | F1: Статья БДДС 3 уровень | G1: ID инвестиционного проекта | H1: Отметка о типе проекта | I1: Объем финансирования инвестиционного проекта, всего, тыс. руб. | J1: Пункт мероприятия Программы ЦТ (Стратегии ЦТ) | K1: Номер в реестре отеч ПО | L1: Класс предмета закупки | M1: Предмет закупки | N1: Подробное описание объекта закупки (товара, работы или услуги) | O1: Отметка о закупке у Отраслевого оператора (Да/Нет) | P1: Сумма с НДС, тыс. руб
P2: План 2026 | Q2: 1-й квартал 2026 | R2: 2-й квартал 2026 | S2: 3-й квартал 2026 | T2: 4-й квартал 2026 | U2: Месяц поставки | V2: План 2027 | W2: План 2028 | X2: План 2029
Q3: План | R3: План | S3: План | T3: План | U3: План
A4: 1 | B4: 2 | C4: 3 | D4: 4 | E4: 5 | F4: 6 | G4: 7 | H4: 8 | I4: 9 | J4: 10 | K4: 11 | L4: 12 | M4: 13 | N4: 14 | O4: 15 | P4: 16 | Q4: 17 | R4: 18 | S4: 19 | T4: 20 | U4: 21 | V4: 22 | W4: 23 | X4: 24
A5: ФГУП "НТЦ "Заря" | C5: Инвестиционный_проект | D5: ИТ_оборудование_и_комплектующие_ИП | E5: 42210103 | F5: Приобретение оборудования для ИТ-инфраструктуры | G5: 075-00012-НП | I5: 2100 | L5: 1. Персональные компьютеры, ноутбуки, мониторы, терминалы | M5: Закупка "Обруч 2 " спецпроверенный комплект | N5: Обеспечение защиты гостайны | O5: Нет | P5: =SUM(Q5:T5) -> 1000 | S5: 1000 | U5: сентябрь | V5: 1100
A6: ФГУП "НТЦ"Заря" | C6: Инвестиционный_проект | D6: ИТ_оборудование_и_комплектующие_ИП | E6: 42210103 | F6: Приобретение оборудования для ИТ-инфраструктуры | G6: 075-00012-НП | I6: 7000 | L6: 1. Персональные компьютеры, ноутбуки, мониторы, терминалы | M6: Закупка АРМ в защищенном исполнении (отечественного производства) | N6: Закупка АРМ в защищеном исполнении | O6: Нет | P6: =SUM(Q6:T6) -> 1000 | S6: 1000 | U6: сентябрь | V6: 5400 | W6: 600
A7: ФГУП "НТЦ "Заря" | C7: Инвестиционный_проект | D7: ИТ_оборудование_и_комплектующие_ИП | E7: 42210103 | F7: Приобретение оборудования для ИТ-инфраструктуры | G7: 075-00011-НП | I7: 320 | L7: 7. Прочее оборудование | M7: Закупка консоли для управления серверным оборудованием (отечественного производства) | N7: Закупка консоли для управления серверным оборудованием (отечественного производства) | O7: Да | P7: =SUM(Q7:T7) -> 320 | T7: 320 | U7: октябрь
A8: ФГУП "НТЦ "Заря" | C8: Инвестиционный_проект | D8: ИТ_оборудование_и_комплектующие_ИП | E8: 42210103 | F8: Приобретение оборудования для ИТ-инфраструктуры | G8: 075-00012-НП | I8: 1850 | K8: 27104 | L8: 3. Сетевое и коммуникационное оборудование | M8: Закупка межсетевого экрана (отечественного производства) | N8: Межсетевой экран UserGate | O8: Да | P8: =SUM(Q8:T8) -> 1530 | S8: 1530 | U8: сентябрь
A9: ФГУП "НТЦ"Заря" | C9: Инвестиционный_проект | D9: ИТ_оборудование_и_комплектующие_ИП | E9: 42210103 | F9: Приобретение оборудования для ИТ-инфраструктуры | G9: 075-00011-НП | I9: 2400 | L9: 6. Печатное оборудование и сканеры | M9: Закупка многофункциональных устройств (отечественного производства) | N9: Закупка МФУ для нужд ФГУП "НТЦ "Заря" | O9: Да | P9: =SUM(Q9:T9) -> 2400 | S9: 2400 | U9: сентябрь
A10: ФГУП "НТЦ "Заря" | C10: Инвестиционный_проект | D10: ИТ_оборудование_и_комплектующие_ИП | E10: 42210103 | F10: Приобретение оборудования для ИТ-инфраструктуры | G10: 075-00011-НП | I10: 16300 | L10: 2. Серверное оборудование, СХД | M10: Закупка серверного оборудования (отечественного производства) | N10: Закупка сервера для системы хранения данных, терминального доступа и подсистемы мониторинга событий информационной безопасности | O10: Да | P10: =SUM(Q10:T10) -> 5600 | T10: 5600 | U10: октябрь | V10: 6350 | W10: 8200 | X10: 10250
A11: ФГУП "НТЦ "Заря" | C11: Инвестиционный_проект | D11: ИТ_оборудование_и_комплектующие_ИП | E11: 42210103 | F11: Приобретение оборудования для ИТ-инфраструктуры | G11: 075-00011-НП | I11: 750 | L11: 3. Сетевое и коммуникационное оборудование | M11: Закупка сетевого оборудования (отечественного производства) | N11: Обеспечение бесперебойной работы ФГУП "НТЦ "Заря" | O11: Да | P11: =SUM(Q11:T11) -> 720 | S11: 720 | U11: сентябрь
A12: ФГУП "НТЦ "Заря" | C12: Инвестиционный_проект | D12: Приобретение_ПО | E12: 42210203 | F12: Приобретение ПО | G12: 075-00012-НП | I12: 2700 | K12: 20006 | L12: 3.1 - Средства защиты от несанкционированного доступа к информации | M12: Закупка средств криптографической защиты информации (АПКШ Континент) | N12: Обеспечение безопасности ФГУП "НТЦ "Заря" | O12: Нет | P12: =SUM(Q12:T12) -> 0 | V12: 2700
A13: ФГУП "НТЦ "Заря" | C13: Операционный_бюджет | D13: Аренда_оборудования_и_вычислительных_мощностей | E13: 41210401 | F13: Аренда ИТ-оборудования и вычислительных мощностей | M13: Аренда стойко-места на ММТС-10 | N13: Аренда стойко-места на ММТС-10 для размещения каналообразуюшего оборудования, обеспечение функционирования оборудования, размещение стоек, предоставление производственных ресуросв | O13: Нет | P13: =SUM(Q13:T13) -> 2000 | Q13: 500 | R13: 500 | S13: 500 | T13: 500 | U13: Каждый месяц | V13: 2000 | W13: 2000
A14: ФГУП "НТЦ"Заря" | C14: Операционный_бюджет | D14: Запчасти_и_расходные_материалы_к_ИТ_оборудованию | E14: 41210201 | F14: Оборудование, мебель (малоценное имущество) | M14: Закупка картриджей для принтеров | N14: Закупка картриджей для замены в принтерах в том числе и в НКЦ | O14: Да | P14: =SUM(Q14:T14) -> 2000 | R14: 2000 | U14: апрель | V14: 2400 | W14: 2880 | X14: 3600
A15: ФГУП "НТЦ"Заря" | C15: Операционный_бюджет | D15: Запчасти_и_расходные_материалы_к_ИТ_оборудованию | E15: 41210201 | F15: Оборудование, мебель (малоценное имущество) | M15: Закупка оптических дисков | N15: Закупка оптических дисков для обеспечения информационного обмена | O15: Да | P15: =SUM(Q15:T15) -> 100 | Q15: 100 | U15: февраль | V15: 120 | W15: 140 | X15: 175
A16: ФГУП "НТЦ"Заря" | C16: Операционный_бюджет | D16: Запчасти_и_расходные_материалы_к_ИТ_оборудованию | E16: 41210201 | F16: Оборудование, мебель (малоценное имущество) | M16: Закупка съемых носителей информации | N16: Закупка съемных носителей информации (ЭП, идентификация пользователей и т.д.) | O16: Да | P16: =SUM(Q16:T16) -> 300 | R16: 300 | U16: апрель | V16: 360 | W16: 432 | X16: 540
A17: ФГУП "НТЦ"Заря" | C17: Операционный_бюджет | D17: ИТ_оборудование_и_комплектующие | E17: 41210201 | F17: Оборудование, мебель (малоценное имущество) | L17: 4. Средства связи | M17: Закупка стационарных телефонных аппаратов | N17: Закупка стационарных телефонных аппаратов | O17: Да | P17: =SUM(Q17:T17) -> 300 | R17: 300 | U17: апрель | V17: 350 | W17: 400 | X17: 500
A18: ФГУП "НТЦ "Заря" | C18: Операционный_бюджет | D18: ИТ_оборудование_и_комплектующие | E18: 41210201 | F18: Оборудование, мебель (малоценное имущество) | L18: 7. Прочее оборудование | M18: Закупка АКБ для ИБП | N18: Закупка АКБ для замены выработавших установленный ресурс в ИБП | O18: Нет | P18: =SUM(Q18:T18) -> 200 | Q18: 100 | S18: 100 | U18: сентябрь | V18: 200 | W18: 200 | X18: 250
A19: ФГУП "НТЦ"Заря" | C19: Операционный_бюджет | D19: ИТ_оборудование_и_комплектующие | E19: 41210201 | F19: Оборудование, мебель (малоценное имущество) | L19: 7. Прочее оборудование | M19: Закупка комплектующих для АРМ | N19: Закупка комплектующицих для АРМ и серверов | O19: Да | P19: =SUM(Q19:T19) -> 1500 | S19: 1500 | U19: сентябрь | V19: 1700 | W19: 2000 | X19: 2500
A20: ФГУП "НТЦ"Заря" | C20: Операционный_бюджет | D20: ИТ_оборудование_и_комплектующие | E20: 41210201 | F20: Оборудование, мебель (малоценное имущество) | L20: 1. Персональные компьютеры, ноутбуки, мониторы, терминалы | M20: Закупка мониторов | N20: Закупка мониторов для нужд ФГУП "НТЦ "Заря" | O20: Да | P20: =SUM(Q20:T20) -> 2300 | S20: 2300 | U20: сентябрь | V20: 2700 | W20: 3200 | X20: 4000
A21: ФГУП "НТЦ"Заря" | C21: Операционный_бюджет | D21: ИТ_оборудование_и_комплектующие | E21: 41210201 | F21: Оборудование, мебель (малоценное имущество) | L21: 1. Персональные компьютеры, ноутбуки, мониторы, терминалы | M21: Закупка ноутбуков | N21: Закупка ноутбуков для нужд ФГУП "НТЦ "Заря" | O21: Да | P21: =SUM(Q21:T21) -> 800 | R21: 800 | U21: апрель | V21: 960 | W21: 1150 | X21: 1437.5
A22: ФГУП "НТЦ"Заря" | C22: Операционный_бюджет | D22: ИТ_оборудование_и_комплектующие | E22: 41210201 | F22: Оборудование, мебель (малоценное имущество) | L22: 1. Персональные компьютеры, ноутбуки, мониторы, терминалы | M22: Закупка системных блоков | N22: Закупка системных блоков для нужд "ФГУП НТЦ "Заря" | O22: Да | P22: =SUM(Q22:T22) -> 3400 | S22: 3400 | U22: сентябрь | V22: 4000 | W22: 4800 | X22: 6000
A23: ФГУП "НТЦ"Заря" | C23: Операционный_бюджет | D23: ИТ_оборудование_и_комплектующие | E23: 41210201 | F23: Оборудование, мебель (малоценное имущество) | L23: 4. Средства связи | M23: Совершенствование корпоративной телефонной связи | N23: Закупка модулей IP-телефонии для телефонной станции МиниКом DX-500 | O23: Нет | P23: =SUM(Q23:T23) -> 350 | T23: 350 | U23: октябрь | V23: 600 | W23: 720 | X23: 900
A24: ФГУП "НТЦ "Заря" | C24: Операционный_бюджет | D24: ИТ_оборудование_и_комплектующие | E24: 41210201 | F24: Оборудование, мебель (малоценное имущество) | L24: 3. Сетевое и коммуникационное оборудование | M24: Создание сети передачи данных с использованием технологии квантового распределения криптографических ключей | N24: Создание сети передачи данных с использованием технологии квантового распределения криптографических ключей | O24: Да | P24: =SUM(Q24:T24) -> 1000 | T24: 1000 | U24: октябрь | V24: 1200 | W24: 1500 | X24: 1875
A25: ФГУП "НТЦ"Заря" | C25: Операционный_бюджет | D25: ИТ_оборудование_и_комплектующие | E25: 41210201 | F25: Оборудование, мебель (малоценное имущество) | L25: 7. Прочее оборудование | M25: Закупка комплектующих для оргтехники | N25: Закупка комплектующих для оргтехники | O25: Да | P25: =SUM(Q25:T25) -> 1000 | Q25: 250 | R25: 250 | S25: 250 | T25: 250 | U25: апрель | V25: 1200 | W25: 1400 | X25: 1750
A26: ФГУП "НТЦ"Заря" | C26: Операционный_бюджет | D26: Программное_обеспечение_лицензии | E26: 41210402 | F26: Приобретение прав пользования ПО (лицензии) | K26: 20157 | L26: 9.11 - Средства управления содержимым (CMS), сайты и портальные решения | M26: Доработка и обновление сайта | N26: Закупка средства управления содержимым сайта, SSL-сертификата, доменного имени | O26: Нет | P26: =SUM(Q26:T26) -> 1000 | R26: 1000 | U26: апрель | V26: 1200 | W26: 1440 | X26: 1800
A27: ФГУП "НТЦ"Заря" | C27: Операционный_бюджет | D27: Программное_обеспечение_лицензии | E27: 41210402 | F27: Приобретение прав пользования ПО (лицензии) | K27: 11953 | L27: 3.17 - Средства автоматизации процессов информационной безопасности | M27: Закупка неисключительных прав на использование программного обеспечения анализа защищенности | N27: Закупка MaxPatrol VM | O27: Нет | P27: =SUM(Q27:T27) -> 2000 | T27: 2000 | U27: февраль | V27: 3000 | W27: =V27*0.15+V27 -> 3450 | X27: =W27*1.25 -> 4312.5
A28: ФГУП "НТЦ "Заря" | C28: Операционный_бюджет | D28: Программное_обеспечение_лицензии | E28: 41210402 | F28: Приобретение прав пользования ПО (лицензии) | L28: 1.4 - Программное обеспечение интернета вещей, робототехники и сенсорики | M28: Закупка специализированного программного обеспечения | N28: Специализированное программное обеспечение, содержащие сведения составляющие государственную тайну | O28: Нет | P28: =SUM(Q28:T28) -> 1000 | R28: 1000 | U28: апрель | V28: 1500 | W28: 2000
A29: ФГУП "НТЦ"Заря" | C29: Операционный_бюджет | D29: Программное_обеспечение_лицензии | E29: 41210402 | F29: Приобретение прав пользования ПО (лицензии) | K29: 207 | L29: 3.6 - Средства антивирусной защиты | M29: Закупка средств антивирусной защиты информации | N29: Поставка неисключительных прав на использование антивирусного средства Kaspersky | O29: Нет | P29: =SUM(Q29:T29) -> 600 | S29: 600 | U29: сентябрь | V29: 700 | W29: 800 | X29: 1000
A30: ФГУП "НТЦ"Заря" | C30: Операционный_бюджет | D30: Программное_обеспечение_лицензии | E30: 41210402 | F30: Приобретение прав пользования ПО (лицензии) | K30: 232 | L30: 3.11 - Средства защиты каналов передачи данных, в том числе криптографическими методами | M30: Закупка средств криптографической защиты информации | N30: приобретение неискулючительных прав на использование СКЗИ Континен-АП | O30: Да | P30: =SUM(Q30:T30) -> 150 | R30: 150 | U30: июнь | V30: 150 | W30: 150 | X30: 187.5
A31: ФГУП "НТЦ "Заря" | C31: Операционный_бюджет | D31: Программное_обеспечение_лицензии | E31: 41210402 | F31: Приобретение прав пользования ПО (лицензии) | K31: 8828 | L31: 3.9 - Средства обнаружения и предотвращения утечек информации | M31: Закупка средств обнаружения и предотвращения утечек информации | N31: Программное обеспечение DLP StaffCop | O31: Да | P31: =SUM(Q31:T31) -> 2000 | T31: 2000 | U31: октябрь
A32: ФГУП "НТЦ "Заря" | C32: Операционный_бюджет | D32: Программное_обеспечение_лицензии | E32: 41210402 | F32: Приобретение прав пользования ПО (лицензии) | K32: 369 | L32: 1.2 - Встроенные системные программы - операционные системы | M32: Оказание услуг по предоставлению неисключительных прав (лицензий) на использование отечественной операционной системы Astra Linux (для рабочих станций и серверов) | N32: Оказание услуг по предоставлению неисключительных прав (лицензий) на использование отечественной операционной системы Astra Linux (для рабочих станций и серверов) | O32: Нет | P32: =SUM(Q32:T32) -> 5100 | S32: 5100 | U32: сентябрь | V32: 6080 | W32: 6360 | X32: 7950
A33: ФГУП "НТЦ "Заря" | C33: Операционный_бюджет | D33: Прочие | E33: 41210403 | F33: Услуги связи (связь, интернет) | M33: Услуги связи | N33: Аренда Потока Е 1 | O33: Нет | P33: =SUM(Q33:T33) -> 340 | Q33: 85 | R33: 85 | S33: 85 | T33: 85 | U33: Каждый квартал | V33: 340 | W33: 340
A34: ФГУП "НТЦ "Заря" | C34: Операционный_бюджет | D34: Прочие | E34: 41210403 | F34: Услуги связи (связь, интернет) | M34: Услуги связи | N34: Обеспеспечение функционирования телефона СПТС | O34: Нет | P34: =SUM(Q34:T34) -> 240 | Q34: 60 | R34: 60 | S34: 60 | T34: 60 | U34: Каждый месяц | V34: 240 | W34: 240
A35: ФГУП "НТЦ "Заря" | C35: Операционный_бюджет | D35: Прочие | E35: 41210403 | F35: Услуги связи (связь, интернет) | M35: Услуги связи | N35: Обслуживание в сетях "Атлас", "Исток" | O35: Нет | P35: =SUM(Q35:T35) -> 480 | Q35: 120 | R35: 120 | S35: 120 | T35: 120 | U35: Каждый квартал | V35: 480 | W35: 480
A36: ФГУП "НТЦ "Заря" | C36: Операционный_бюджет | D36: Прочие | E36: 41210403 | F36: Услуги связи (связь, интернет) | M36: Услуги связи | N36: Оказание услуг виртуальных частных сетей на основе сети передачи данных | O36: Нет | P36: =SUM(Q36:T36) -> 100 | Q36: 25 | R36: 25 | S36: 25 | T36: 25 | U36: Каждый квартал | V36: 100 | W36: 100
A37: ФГУП "НТЦ "Заря" | C37: Операционный_бюджет | D37: Прочие | E37: 41210403 | F37: Услуги связи (связь, интернет) | M37: Услуги связи | N37: Оказание услуг виртуальных частных сетей на основе сети передачи данных (VPN L3, Минобороны России) | O37: Нет | P37: =SUM(Q37:T37) -> 100 | Q37: 25 | R37: 25 | S37: 25 | T37: 25 | U37: Каждый квартал | V37: 25 | W37: 25
A38: ФГУП "НТЦ "Заря" | C38: Операционный_бюджет | D38: Прочие | E38: 41210403 | F38: Услуги связи (связь, интернет) | M38: Услуги связи | N38: Предоставление в пользование канала (MPLS L2VPN) | O38: Нет | P38: =SUM(Q38:T38) -> 440 | Q38: 110 | R38: 110 | S38: 110 | T38: 110 | U38: Каждый квартал | V38: 440 | W38: 440
A39: ФГУП "НТЦ "Заря" | C39: Операционный_бюджет | D39: Прочие | E39: 41210403 | F39: Услуги связи (связь, интернет) | M39: Услуги связи | N39: Услуги связи ОАО "КОМКОР" | O39: Нет | P39: =SUM(Q39:T39) -> 260 | Q39: 65 | R39: 65 | S39: 65 | T39: 65 | U39: Каждый квартал | V39: 260 | W39: 260
A40: ФГУП "НТЦ "Заря" | C40: Операционный_бюджет | D40: Прочие | E40: 41210403 | F40: Услуги связи (связь, интернет) | M40: Услуги связи | N40: Услуги связи ПАО "Ростелеком" | O40: Нет | P40: =SUM(Q40:T40) -> 80 | Q40: 20 | R40: 20 | S40: 20 | T40: 20 | U40: Каждый квартал | V40: 80 | W40: 80
...

Sheet Программа ЦТ
B2: Код | C2: Направление программы /мероприятие | K2: Дата начала реализации | M2: Дата окончания реализации | O2: Отметка о проведении работ собственными силами | P2: 2024 | Q2: 2025 | R2: 2026 | S2: 2027
K3: месяц | L3: год | M3: месяц | N3: год
B4: 1 | C4: Цифровая система управления | P4: =SUM(P5:P9) -> 0 | Q4: =SUM(Q5:Q9) -> 0 | R4: =SUM(R5:R9) -> 0 | S4: =SUM(S5:S9) -> 0
B5: 1.1
B6: 1.2
B7: 1.3
B8: 1.4
B9: 1.5
B10: 2 | C10: Цифровизации производства и жизненного цикла изделий | P10: =SUM(P11:P15) -> 0 | Q10: =SUM(Q11:Q15) -> 0 | R10: =SUM(R11:R15) -> 0 | S10: =SUM(S11:S15) -> 0
B11: 2.1
B12: 2.2
B13: 2.3
B14: 2.4
B15: 2.5
B16: 3 | C16: Цифровая система управления данными | P16: =SUM(P17:P23) -> 0 | Q16: =SUM(Q17:Q23) -> 0 | R16: =SUM(R17:R23) -> 0 | S16: =SUM(S17:S23) -> 0
B17: 3.1
B18: 3.2
B19: 3.3
B20: 3.4
B21: 3.5
B22: 3.6
B23: 3.7
B24: 4 | C24: Цифровые компетенции персонала | O24: =IF(COUNTIFS('План Факт 2025'!$J$5:$J$58,'Программа ЦТ'!$D24,'План Факт 2025'!$C$5:$C$58,"ФОТ")>0,"Собственные силы","") | P24: =SUM(P25:P29) -> 0 | Q24: =SUM(Q25:Q29) -> 0 | R24: =SUM(R25:R29) -> 0 | S24: =SUM(S25:S29) -> 0
B25: 4.1
B26: 4.2
B27: 4.3
B28: 4.4
B29: 4.5
B30: 5 | C30: Импортозамещение | O30: =IF(COUNTIFS('План Факт 2025'!$J$5:$J$58,'Программа ЦТ'!$D30,'План Факт 2025'!$C$5:$C$58,"ФОТ")>0,"Собственные силы","") | P30: =SUM(P31:P37) -> 0 | Q30: =SUM(Q31:Q37) -> 0 | R30: =SUM(R31:R37) -> 0 | S30: =SUM(S31:S37) -> 0
B31: 5.1
B32: 5.2
B33: 5.3
B34: 5.4
B35: 5.5
B36: 5.6
B37: 5.7
B38: 6 | C38: Обеспечение безопасности информации (данных) и ИТ-инфраструктуры | O38: =IF(COUNTIFS('План Факт 2025'!$J$5:$J$58,'Программа ЦТ'!$D38,'План Факт 2025'!$C$5:$C$58,"ФОТ")>0,"Собственные силы","") | P38: =SUM(P39:P45) -> 0 | Q38: =SUM(Q39:Q45) -> 0 | R38: =SUM(R39:R45) -> 0 | S38: =SUM(S39:S45) -> 0
B39: 6.1
B40: 6.2
B41: 6.3
...

Sheet Свод ДДС
A1: № п/п | C1: Бюджет ДДС в части ИТ и цифровизации | D1: План 2026 | E1: План 2027 | F1: План 2028 | G1: План 2029
A2: 1 | B2: Операционные затраты | D2: =SUM(D3:D12) -> 40960 | E2: =SUM(E3:E12) -> 46485 | F2: =SUM(F3:F12) -> 53683 | G2: =SUM(G3:G12) -> 55677.5
A3: 1.1 | C3: Программное_обеспечение_лицензии | D3: =SUMIF('План 2026-2028'!$D$5:$D$58,'Свод ДДС'!$C3,'План 2026-2028'!$P$5:$P$58) -> 11850 | E3: =SUMIF('План 2026-2028'!$D$5:$D$58,'Свод ДДС'!$C3,'План 2026-2028'!$V$5:$V$58) -> 12630 | F3: =SUMIF('План 2026-2028'!$D$5:$D$58,'Свод ДДС'!$C3,'План 2026-2028'!$W$5:$W$58) -> 14200 | G3: =SUMIF('План 2026-2028'!$D$5:$D$58,'Свод ДДС'!$C3,'План 2026-2028'!$X$5:$X$58) -> 15250
A4: 1.2 | C4: ИТ_оборудование_и_комплектующие | D4: =SUMIF('План 2026-2028'!$D$5:$D$58,'Свод ДДС'!$C4,'План 2026-2028'!$P$5:$P$58) -> 10850 | E4: =SUMIF('План 2026-2028'!$D$5:$D$58,'Свод ДДС'!$C4,'План 2026-2028'!$V$5:$V$58) -> 12910 | F4: =SUMIF('План 2026-2028'!$D$5:$D$58,'Свод ДДС'!$C4,'План 2026-2028'!$W$5:$W$58) -> 15370 | G4: =SUMIF('План 2026-2028'!$D$5:$D$58,'Свод ДДС'!$C4,'План 2026-2028'!$X$5:$X$58) -> 19212.5
A5: 1.3 | C5: Запчасти_и_расходные_материалы_к_ИТ_оборудованию | D5: =SUMIF('План 2026-2028'!$D$5:$D$58,'Свод ДДС'!$C5,'План 2026-2028'!$P$5:$P$58) -> 2400 | E5: =SUMIF('План 2026-2028'!$D$5:$D$58,'Свод ДДС'!$C5,'План 2026-2028'!$V$5:$V$58) -> 2880 | F5: =SUMIF('План 2026-2028'!$D$5:$D$58,'Свод ДДС'!$C5,'План 2026-2028'!$W$5:$W$58) -> 3452 | G5: =SUMIF('План 2026-2028'!$D$5:$D$58,'Свод ДДС'!$C5,'План 2026-2028'!$X$5:$X$58) -> 4315
A6: 1.4 | C6: Услуги_внешней_техподдержки | D6: =SUMIF('План 2026-2028'!$D$5:$D$58,'Свод ДДС'!$C6,'План 2026-2028'!$P$5:$P$58) -> 8800 | E6: =SUMIF('План 2026-2028'!$D$5:$D$58,'Свод ДДС'!$C6,'План 2026-2028'!$V$5:$V$58) -> 10700 | F6: =SUMIF('План 2026-2028'!$D$5:$D$58,'Свод ДДС'!$C6,'План 2026-2028'!$W$5:$W$58) -> 12620 | G6: =SUMIF('План 2026-2028'!$D$5:$D$58,'Свод ДДС'!$C6,'План 2026-2028'!$X$5:$X$58) -> 13150
A7: 1.5 | C7: Ремонт_ИТ_инфраструктуры | D7: =SUMIF('План 2026-2028'!$D$5:$D$58,'Свод ДДС'!$C7,'План 2026-2028'!$P$5:$P$58) -> 800 | E7: =SUMIF('План 2026-2028'!$D$5:$D$58,'Свод ДДС'!$C7,'План 2026-2028'!$V$5:$V$58) -> 880 | F7: =SUMIF('План 2026-2028'!$D$5:$D$58,'Свод ДДС'!$C7,'План 2026-2028'!$W$5:$W$58) -> 1076 | G7: =SUMIF('План 2026-2028'!$D$5:$D$58,'Свод ДДС'!$C7,'План 2026-2028'!$X$5:$X$58) -> 0
A8: 1.6 | C8: Аренда_оборудования_и_вычислительных_мощностей | D8: =SUMIF('План 2026-2028'!$D$5:$D$58,'Свод ДДС'!$C8,'План 2026-2028'!$P$5:$P$58) -> 2000 | E8: =SUMIF('План 2026-2028'!$D$5:$D$58,'Свод ДДС'!$C8,'План 2026-2028'!$V$5:$V$58) -> 2000 | F8: =SUMIF('План 2026-2028'!$D$5:$D$58,'Свод ДДС'!$C8,'План 2026-2028'!$W$5:$W$58) -> 2000 | G8: =SUMIF('План 2026-2028'!$D$5:$D$58,'Свод ДДС'!$C8,'План 2026-2028'!$X$5:$X$58) -> 0
A9: 1.7 | C9: Услуги_связи | D9: =SUMIF('План 2026-2028'!$D$5:$D$58,'Свод ДДС'!$C9,'План 2026-2028'!$P$5:$P$58) -> 520 | E9: =SUMIF('План 2026-2028'!$D$5:$D$58,'Свод ДДС'!$C9,'План 2026-2028'!$V$5:$V$58) -> 600 | F9: =SUMIF('План 2026-2028'!$D$5:$D$58,'Свод ДДС'!$C9,'План 2026-2028'!$W$5:$W$58) -> 700 | G9: =SUMIF('План 2026-2028'!$D$5:$D$58,'Свод ДДС'!$C9,'План 2026-2028'!$X$5:$X$58) -> 875
A10: 1.8 | C10: Услуги_по_внедрению_информационных_систем_(непроектные) | D10: =SUMIF('План 2026-2028'!$D$5:$D$58,'Свод ДДС'!$C10,'План 2026-2028'!$P$5:$P$58) -> 0 | E10: =SUMIF('План 2026-2028'!$D$5:$D$58,'Свод ДДС'!$C10,'План 2026-2028'!$V$5:$V$58) -> 0 | F10: =SUMIF('План 2026-2028'!$D$5:$D$58,'Свод ДДС'!$C10,'План 2026-2028'!$W$5:$W$58) -> 0 | G10: =SUMIF('План 2026-2028'!$D$5:$D$58,'Свод ДДС'!$C10,'План 2026-2028'!$X$5:$X$58) -> 0
A11: 1.9 | C11: Сопровождение_информационных_систем | D11: =SUMIF('План 2026-2028'!$D$5:$D$58,'Свод ДДС'!$C11,'План 2026-2028'!$P$5:$P$58) -> 1700 | E11: =SUMIF('План 2026-2028'!$D$5:$D$58,'Свод ДДС'!$C11,'План 2026-2028'!$V$5:$V$58) -> 1920 | F11: =SUMIF('План 2026-2028'!$D$5:$D$58,'Свод ДДС'!$C11,'План 2026-2028'!$W$5:$W$58) -> 2300 | G11: =SUMIF('План 2026-2028'!$D$5:$D$58,'Свод ДДС'!$C11,'План 2026-2028'!$X$5:$X$58) -> 2875
A12: 1.10 | C12: Прочие | D12: =SUMIF('План 2026-2028'!$D$5:$D$58,'Свод ДДС'!$C12,'План 2026-2028'!$P$5:$P$58) -> 2040 | E12: =SUMIF('План 2026-2028'!$D$5:$D$58,'Свод ДДС'!$C12,'План 2026-2028'!$V$5:$V$58) -> 1965 | F12: =SUMIF('План 2026-2028'!$D$5:$D$58,'Свод ДДС'!$C12,'План 2026-2028'!$W$5:$W$58) -> 1965 | G12: =SUMIF('План 2026-2028'!$D$5:$D$58,'Свод ДДС'!$C12,'План 2026-2028'!$X$5:$X$58) -> 0
A13: 2 | B13: Инвестиционные проекты | D13: =SUM(D14:D17) -> 12570 | E13: =SUM(E14:E17) -> 15550 | F13: =SUM(F14:F17) -> 8800 | G13: =SUM(G14:G17) -> 10250
A14: 2.1 | C14: Приобретение_ПО | D14: =SUMIF('План 2026-2028'!$D$5:$D$58,'Свод ДДС'!$C14,'План 2026-2028'!$P$5:$P$58) -> 0 | E14: =SUMIF('План 2026-2028'!$D$5:$D$58,'Свод ДДС'!$C14,'План 2026-2028'!$V$5:$V$58) -> 2700 | F14: =SUMIF('План 2026-2028'!$D$5:$D$58,'Свод ДДС'!$C14,'План 2026-2028'!$W$5:$W$58) -> 0 | G14: =SUMIF('План 2026-2028'!$D$5:$D$58,'Свод ДДС'!$C14,'План 2026-2028'!$X$5:$X$58) -> 0
A15: 2.2 | C15: ИТ_оборудование_и_комплектующие_ИП | D15: =SUMIF('План 2026-2028'!$D$5:$D$58,'Свод ДДС'!$C15,'План 2026-2028'!$P$5:$P$58) -> 12570 | E15: =SUMIF('План 2026-2028'!$D$5:$D$58,'Свод ДДС'!$C15,'План 2026-2028'!$V$5:$V$58) -> 12850 | F15: =SUMIF('План 2026-2028'!$D$5:$D$58,'Свод ДДС'!$C15,'План 2026-2028'!$W$5:$W$58) -> 8800 | G15: =SUMIF('План 2026-2028'!$D$5:$D$58,'Свод ДДС'!$C15,'План 2026-2028'!$X$5:$X$58) -> 10250
A16: 2.3 | C16: Услуги_сторонних_организаций | D16: =SUMIF('План 2026-2028'!$D$5:$D$58,'Свод ДДС'!$C16,'План 2026-2028'!$P$5:$P$58) -> 0 | E16: =SUMIF('План 2026-2028'!$D$5:$D$58,'Свод ДДС'!$C16,'План 2026-2028'!$V$5:$V$58) -> 0 | F16: =SUMIF('План 2026-2028'!$D$5:$D$58,'Свод ДДС'!$C16,'План 2026-2028'!$W$5:$W$58) -> 0 | G16: =SUMIF('План 2026-2028'!$D$5:$D$58,'Свод ДДС'!$C16,'План 2026-2028'!$X$5:$X$58) -> 0
A17: 2.4 | C17: Прочие_ИП | D17: =SUMIF('План 2026-2028'!$D$5:$D$58,'Свод ДДС'!$C17,'План 2026-2028'!$P$5:$P$58) -> 0 | E17: =SUMIF('План 2026-2028'!$D$5:$D$58,'Свод ДДС'!$C17,'План 2026-2028'!$V$5:$V$58) -> 0 | F17: =SUMIF('План 2026-2028'!$D$5:$D$58,'Свод ДДС'!$C17,'План 2026-2028'!$W$5:$W$58) -> 0 | G17: =SUMIF('План 2026-2028'!$D$5:$D$58,'Свод ДДС'!$C17,'План 2026-2028'!$X$5:$X$58) -> 0
A18: ИТОГО | D18: =D2+D13 -> 53530 | E18: =E2+E13 -> 62035 | F18: =F2+F13 -> 62483 | G18: =G2+G13 -> 65927.5
A19: в т.ч. закупки у Отраслевого оператора | D19: =SUMIF('План Факт 2025'!$O$5:$O$58,"да",'План Факт 2025'!$Q$5:$Q$58) -> 38200 | E19: =SUMIF('План 2026-2028'!$O$5:$O$58,"да",'План 2026-2028'!$V$5:$V$58) -> 23690 | F19: =SUMIF('План 2026-2028'!$O$5:$O$58,"да",'План 2026-2028'!$W$5:$W$58) -> 28852 | G19: =SUMIF('План 2026-2028'!$O$5:$O$58,"да",'План 2026-2028'!$X$5:$X$58) -> 36065
D20: =IFERROR(D19/D18,"") -> 0.71361853 | E20: =IFERROR(E19/E18,"") -> 0.3818812 | F20: =IFERROR(F19/F18,"") -> 0.4617576 | G20: =IFERROR(G19/G18,"") -> 0.54704031
A21: в т.ч. Инвестиционные проекты | D21: =SUM(D22:D32) -> 10850 | E21: =SUM(E22:E32) -> 15550 | F21: =SUM(F22:F32) -> 8800 | G21: =SUM(G22:G32) -> 10250
C22: {=IFERROR(INDEX('План Факт 2025'!$G$5:$G$30, MATCH(0,COUNTIF($C$21:C21,'План Факт 2025'!$G$5:$G$30&"") + IF('План Факт 2025'!$G$5:$G$30="",1,0), 0)), "")} -> 075-00011-НП | D22: =IF(C22<>"",SUMIF('План Факт 2025'!$G$5:$G$58,'Свод ДДС'!$C22,'План Факт 2025'!$Q$5:$Q$58),"") -> 10850 | E22: =IF(C22<>"",SUMIF('План 2026-2028'!$G$5:$G$14,'Свод ДДС'!$C22,'План 2026-2028'!$V$5:$V$58),"") -> 6350 | F22: =IF(C22<>"",SUMIF('План 2026-2028'!$G$5:$G$14,'Свод ДДС'!$C22,'План 2026-2028'!$W$5:$W$58),"") -> 8200 | G22: =IF(C22<>"",SUMIF('План 2026-2028'!$G$5:$G$14,'Свод ДДС'!$C22,'План 2026-2028'!$X$5:$X$58),"") -> 10250
C23: 075-00012-НП | D23: =IF(C23<>"",SUMIF('План Факт 2025'!$G$5:$G$58,'Свод ДДС'!$C23,'План Факт 2025'!$Q$5:$Q$58),"") -> 0 | E23: =IF(C23<>"",SUMIF('План 2026-2028'!$G$5:$G$14,'Свод ДДС'!$C23,'План 2026-2028'!$V$5:$V$58),"") -> 9200 | F23: =IF(C23<>"",SUMIF('План 2026-2028'!$G$5:$G$14,'Свод ДДС'!$C23,'План 2026-2028'!$W$5:$W$58),"") -> 600 | G23: =IF(C23<>"",SUMIF('План 2026-2028'!$G$5:$G$14,'Свод ДДС'!$C23,'План 2026-2028'!$X$5:$X$58),"") -> 0
C24: {=IFERROR(INDEX('План Факт 2025'!$G$5:$G$30, MATCH(0,COUNTIF($C$21:C23,'План Факт 2025'!$G$5:$G$30&"") + IF('План Факт 2025'!$G$5:$G$30="",1,0), 0)), "")} | D24: =IF(C24<>"",SUMIF('План Факт 2025'!$G$5:$G$58,'Свод ДДС'!$C24,'План Факт 2025'!$Q$5:$Q$58),"") | E24: =IF(C24<>"",SUMIF('План 2026-2028'!$G$5:$G$14,'Свод ДДС'!$C24,'План 2026-2028'!$V$5:$V$58),"") | F24: =IF(C24<>"",SUMIF('План 2026-2028'!$G$5:$G$14,'Свод ДДС'!$C24,'План 2026-2028'!$W$5:$W$58),"") | G24: =IF(C24<>"",SUMIF('План 2026-2028'!$G$5:$G$14,'Свод ДДС'!$C24,'План 2026-2028'!$X$5:$X$58),"")
C25: {=IFERROR(INDEX('План Факт 2025'!$G$5:$G$30, MATCH(0,COUNTIF($C$21:C24,'План Факт 2025'!$G$5:$G$30&"") + IF('План Факт 2025'!$G$5:$G$30="",1,0), 0)), "")} | D25: =IF(C25<>"",SUMIF('План Факт 2025'!$G$5:$G$58,'Свод ДДС'!$C25,'План Факт 2025'!$Q$5:$Q$58),"") | E25: =IF(C25<>"",SUMIF('План 2026-2028'!$G$5:$G$14,'Свод ДДС'!$C25,'План 2026-2028'!$V$5:$V$58),"") | F25: =IF(C25<>"",SUMIF('План 2026-2028'!$G$5:$G$14,'Свод ДДС'!$C25,'План 2026-2028'!$W$5:$W$58),"") | G25: =IF(C25<>"",SUMIF('План 2026-2028'!$G$5:$G$14,'Свод ДДС'!$C25,'План 2026-2028'!$X$5:$X$58),"")
C26: {=IFERROR(INDEX('План Факт 2025'!$G$5:$G$30, MATCH(0,COUNTIF($C$21:C25,'План Факт 2025'!$G$5:$G$30&"") + IF('План Факт 2025'!$G$5:$G$30="",1,0), 0)), "")} | D26: =IF(C26<>"",SUMIF('План Факт 2025'!$G$5:$G$58,'Свод ДДС'!$C26,'План Факт 2025'!$Q$5:$Q$58),"") | E26: =IF(C26<>"",SUMIF('План 2026-2028'!$G$5:$G$14,'Свод ДДС'!$C26,'План 2026-2028'!$V$5:$V$58),"") | F26: =IF(C26<>"",SUMIF('План 2026-2028'!$G$5:$G$14,'Свод ДДС'!$C26,'План 2026-2028'!$W$5:$W$58),"") | G26: =IF(C26<>"",SUMIF('План 2026-2028'!$G$5:$G$14,'Свод ДДС'!$C26,'План 2026-2028'!$X$5:$X$58),"")
C27: {=IFERROR(INDEX('План Факт 2025'!$G$5:$G$30, MATCH(0,COUNTIF($C$21:C26,'План Факт 2025'!$G$5:$G$30&"") + IF('План Факт 2025'!$G$5:$G$30="",1,0), 0)), "")} | D27: =IF(C27<>"",SUMIF('План Факт 2025'!$G$5:$G$58,'Свод ДДС'!$C27,'План Факт 2025'!$Q$5:$Q$58),"") | E27: =IF(C27<>"",SUMIF('План 2026-2028'!$G$5:$G$14,'Свод ДДС'!$C27,'План 2026-2028'!$V$5:$V$58),"") | F27: =IF(C27<>"",SUMIF('План 2026-2028'!$G$5:$G$14,'Свод ДДС'!$C27,'План 2026-2028'!$W$5:$W$58),"") | G27: =IF(C27<>"",SUMIF('План 2026-2028'!$G$5:$G$14,'Свод ДДС'!$C27,'План 2026-2028'!$X$5:$X$58),"")
C28: {=IFERROR(INDEX('План Факт 2025'!$G$5:$G$30, MATCH(0,COUNTIF($C$21:C27,'План Факт 2025'!$G$5:$G$30&"") + IF('План Факт 2025'!$G$5:$G$30="",1,0), 0)), "")} | D28: =IF(C28<>"",SUMIF('План Факт 2025'!$G$5:$G$58,'Свод ДДС'!$C28,'План Факт 2025'!$Q$5:$Q$58),"") | E28: =IF(C28<>"",SUMIF('План 2026-2028'!$G$5:$G$14,'Свод ДДС'!$C28,'План 2026-2028'!$V$5:$V$58),"") | F28: =IF(C28<>"",SUMIF('План 2026-2028'!$G$5:$G$14,'Свод ДДС'!$C28,'План 2026-2028'!$W$5:$W$58),"") | G28: =IF(C28<>"",SUMIF('План 2026-2028'!$G$5:$G$14,'Свод ДДС'!$C28,'План 2026-2028'!$X$5:$X$58),"")
